Workbook
Name Slicer_Channel: #N/A
Name Slicer_Country: #N/A
Name Slicer_OrderDate: #N/A
Name Slicer_ProductCategory: #N/A
Name Slicer_Region: #N/A
Name Slicer_Salesperson: #N/A

Sheet Brief
A1: Assignment
A2: Excel Mastery Assignment: Sales Operations & Analytics
A4: Overview:
A5: You are an analyst for a multi-regional electronics distributor. The 'Data' sheet contains 632 rows and 15 columns of transactional data with intentional data-quality issues.
A6: Your job is to clean, enrich, analyze, and present insights via a dynamic dashboard.
A8: Part A — Data Cleaning & Preparation:
A9: 1) Create a staging table where you:
A10: • Remove exact duplicate rows (define and document your duplicate criteria).
A11: • Fix data types (dates as Dates, numeric fields as numbers).
A12: • Handle missing values for City, Salesperson, and Channel using reasonable business logic (document your approach).
A13: • Flag and correct suspicious UnitPrice values (e.g., negative prices) and discounts (e.g., > 30%).
A14: • Ensure RequiredDate is not earlier than OrderDate; where it is, impute a corrected RequiredDate (explain your rule).
... A67: 15) Ensure your dashboard responds to slicers without broken references.

Sheet Raw_Data
A1: OrderID | B1: OrderDate | C1: RequiredDate | D1: Region | E1: Country | F1: City | G1: CustomerSegment | H1: Channel | I1: Salesperson | J1: ProductCategory | K1: SKU | L1: UnitCost | M1: UnitPrice | N1: DiscountPct | O1: Quantity
A2: ORD-2024-275203 | B2: 45362 | C2: 45388 | D2: Africa | E2: Kenya | F2: Kisumu | G2: Corporate | H2: Retail | I2: C. Otieno | J2: Components | K2: CMP-8270 | L2: 279.24 | M2: 608.9 | N2: 0.112 | O2: 9
A3: ORD-2024-358795 | B3: 45588 | C3: 45587 | D3: Africa | E3: Nigeria | F3: Port Harcourt | G3: Education | H3: Online | I3: J. Njeri | J3: Printers | K3: PRN-9322 | L3: 1084.39 | M3: 759.33 | N3: 0.237 | O3: 31
A4: ORD-2023-373538 | B4: 44985 | C4: 45010 | D4: Africa | E4: Kenya | F4: Nairobi | G4: Corporate | H4: Retail | I4: I. Johnson | J4: Networking | K4: NET-9666 | L4: 1460.76 | M4: -30.66 | N4: 0.131 | O4: 12
A5: ORD-2025-168148 | B5: 45745 | C5: 45749 | D5: Africa | E5: Nigeria | F5: Lagos | G5: Non-Profit | H5: Marketplace | I5: G. Dubois | J5: Phones | K5: PHN-4556 | L5: 259.93 | M5: 255.94 | N5: 0.072 | O5: 22
A6: ORD-2023-824839 | B6: 45266 | C6: 45291 | D6: Asia | E6: Japan | F6: Osaka | G6: Consumer | H6: Retail | I6: L. Okafor | J6: Printers | K6: PRN-8041 | L6: 663.03 | M6: 813.51 | N6: 0.102 | O6: 15
A7: ORD-2023-723587 | B7: 44928 | C7: 44931 | D7: Americas | E7: Canada | F7: Toronto | G7: Corporate | H7: Distributor | I7: B. Chen | J7: Laptops | K7: LAP-8555 | L7: 315.87 | M7: 591.68 | N7: 0 | O7: 7
A8: ORD-2024-336584 | B8: 45653 | C8: 45671 | D8: Asia | E8: India | F8: Bengaluru | G8: Small Business | H8: Marketplace | I8: E. Garcia | J8: Monitors | K8: MON-8629 | L8: 586.07 | M8: 845.97 | N8: 0.147 | O8: 4
A9: ORD-2023-112666 | B9: 44941 | C9: 44939 | D9: Africa | E9: Nigeria | F9: Abuja | G9: Education | H9: Online | I9: O. Wang | J9: Printers | K9: PRN-6276 | L9: 28.38 | M9: 47.22 | N9: 0.194 | O9: 18
A10: ORD-2024-589570 | B10: 45416 | C10: 45441 | D10: Africa | E10: Nigeria | F10: Abuja | G10: Non-Profit | H10: Marketplace | I10: O. Wang | J10: Monitors | K10: MON-6892 | L10: 1295.34 | M10: 2530.81 | N10: 0.031 | O10: 6
A11: ORD-2025-997421 | B11: 45798 | C11: 45817 | D11: Americas | E11: Brazil | F11: São Paulo | G11: Non-Profit | H11: Online | I11: A. Patel | J11: Components | K11: CMP-3731 | L11: 1331.38 | M11: 2309.56 | N11: 0.149 | O11: 31
A12: ORD-2024-210687 | B12: 45319 | C12: 45331 | D12: Europe | E12: Germany | F12: Berlin | G12: Corporate | H12: Online | I12: G. Dubois | J12: Accessories | K12: ACC-7938 | L12: 644.17 | M12: 700.12 | N12: 0.006 | O12: 23
A13: ORD-2025-515515 | B13: 45660 | C13: 45680 | D13: Asia | E13: Japan | F13: Osaka | G13: Corporate | H13: Distributor | I13: F. Müller | J13: Phones | K13: PHN-7019 | L13: 908.6 | M13: 691.37 | N13: 0.25 | O13: 20
... A34: ORD-2025-474710 | B34: 45862 | C34: 45875 | D34: Africa | E34: South Africa | F34: Johannesburg | G34: Education | H34: Marketplace | I34: D. Smith | J34: Networking | K34: NET-7966 | L34: 1463.9 | M34: 2633.02 | N34: 0.084 | O34: 4
A35: ORD-2024-629525 | B35: 45400 | C35: 45420 | D35: Europe | E35: United Kingdom | F35: London | G35: Non-Profit | I35: D. Smith | J35: Laptops | K35: LAP-9932 | L35: 645.33 | M35: 1321.85 | N35: 0 | O35: 10
A36: ORD-2024-167215 | B36: 45527 | C36: 45525 | D36: Africa | E36: South Africa | F36: Johannesburg | G36: Education | H36: Retail | I36: E. Garcia | J36: Components | K36: CMP-1559 | L36: 1432.52 | M36: 3036.87 | N36: 0 | O36: 9
A37: ORD-2023-864121 | B37: 45012 | C37: 45038 | D37: Asia | E37: India | F37: Delhi | G37: Non-Profit | H37: Marketplace | I37: J. Njeri | J37: Printers | K37: PRN-4506 | L37: 178.53 | M37: 199.37 | N37: 0.101 | O37: 37
A38: ORD-2024-692673 | B38: 45358 | C38: 45376 | D38: Europe | E38: Germany | F38: Munich | G38: Corporate | H38: Online | I38: B. Chen | J38: Components | K38: CMP-7617 | L38: 712.84 | M38: 927.51 | N38: 0.243 | O38: 27
A39: ORD-2025-718992 | B39: 45832 | C39: 45848 | D39: Asia | E39: China | F39: Shanghai | G39: Enterprise | H39: Direct | I39: N. Brown | J39: Components | K39: CMP-8390 | L39: 757.19 | M39: 1735.41 | N39: 0.136 | O39: 8
A40: ORD-2024-599522 | B40: 45401 | C40: 45418 | D40: Africa | E40: Nigeria | F40: Port Harcourt | G40: Non-Profit | H40: Online | I40: A. Patel | J40: Printers | K40: PRN-7303 | L40: 865.33 | M40: 1395.64 | N40: 0.175 | O40: 13
A41: ORD-2023-651638 | B41: 45094 | C41: 45101 | D41: Americas | E41: USA | F41: San Francisco | G41: Corporate | H41: Retail | I41: I. Johnson | J41: Printers | K41: PRN-6536 | L41: 313.99 | M41: 454.42 | N41: 0.129 | O41: 9
A42: ORD-2024-635626 | B42: 45531 | C42: 45554 | D42: Europe | E42: Germany | F42: Berlin | G42: Small Business | H42: Direct | I42: D. Smith | J42: Monitors | K42: MON-9967 | L42: 1024.01 | M42: 1580.97 | N42: 0.037 | O42: 27
A43: ORD-2024-296582 | B43: 45302 | C43: 45324 | D43: Africa | E43: South Africa | F43: Durban | G43: Consumer | H43: Online | I43: K. Singh | J43: Networking | K43: NET-1412 | L43: 1206.2 | M43: 1759.79 | N43: 0 | O43: 6
A44: ORD-2024-998320 | B44: 45590 | C44: 45610 | D44: Africa | E44: Kenya | F44: Mombasa | G44: Corporate | H44: Direct | I44: H. Kim | J44: Printers | K44: PRN-3143 | L44: 1396.48 | M44: 3204.5 | N44: 0.318 | O44: 14
A45: ORD-2025-820255 | B45: 45806 | C45: 45828 | D45: Europe | E45: Germany | F45: Berlin | G45: Corporate | H45: Direct | I45: A. Patel | J45: Printers | K45: PRN-9787 | L45: 483.47 | M45: 1135.43 | N45: 0.146 | O45: 11
A46: ORD-2024-389336 | B46: 45432 | C46: 45445 | D46: Americas | E46: Canada | F46: Vancouver | G46: Enterprise | H46: Marketplace | I46: K. Singh | J46: Components | K46: CMP-5946 | L46: 675.43 | M46: 996.36 | N46: 0.182 | O46: 22
A47: ORD-2023-308124 | B47: 45035 | C47: 45046 | D47: Asia | E47: India | F47: Delhi | G47: Small Business | H47: Retail | I47: A. Patel | J47: Networking | K47: NET-2062 | L47: 826.55 | M47: 1397.05 | N47: 0.169 | O47: 28
... A77: ORD-2023-722117 | B77: 45187 | C77: 45207 | D77: Asia | E77: India | F77: Delhi | G77: Small Business | H77: Direct | I77: B. Chen | J77: Components | K77: CMP-1009 | L77: 825.64 | M77: 1108.43 | N77: 0.114 | O77: 7
A78: ORD-2024-446699 | B78: 45532 | C78: 45560 | D78: Americas | E78: Brazil | F78: Rio de Janeiro | G78: Non-Profit | H78: Online | J78: Accessories | K78: ACC-4490 | L78: 1394.65 | M78: 3144.1 | N78: 0.134 | O78: 13
A79: ORD-2024-451005 | B79: 45473 | C79: 45471 | D79: Americas | E79: Brazil | F79: Rio de Janeiro | G79: Small Business | H79: Direct | I79: L. Okafor | J79: Accessories | K79: ACC-9162 | L79: 1112.98 | M79: 2095.73 | N79: 0.072 | O79: 17
A80: ORD-2023-290279 | B80: 45091 | C80: 45093 | D80: Europe | E80: United Kingdom | F80: Manchester | G80: Non-Profit | H80: Direct | I80: K. Singh | J80: Components | K80: CMP-5820 | L80: 357.36 | M80: 703.62 | N80: 0.257 | O80: 20
A81: ORD-2024-192263 | B81: 45617 | C81: 45647 | D81: Europe | E81: France | F81: Marseille | G81: Small Business | H81: Direct | I81: I. Johnson | J81: Monitors | K81: MON-7943 | L81: 1122.68 | M81: 1997.19 | N81: 0.186 | O81: 3
A82: ORD-2023-159379 | B82: 44965 | C82: 44968 | D82: Africa | E82: South Africa | F82: Cape Town | G82: Corporate | H82: Direct | I82: M. Rossi | J82: Networking | K82: NET-5018 | L82: 1410.05 | M82: 2763.95 | N82: 0.161 | O82: 26
A83: ORD-2023-343322 | B83: 45157 | C83: 45181 | D83: Americas | E83: Canada | F83: Vancouver | G83: Enterprise | H83: Retail | I83: I. Johnson | J83: Printers | K83: PRN-9669 | L83: 1183.95 | M83: 1503.53 | N83: 0.241 | O83: 16
A84: ORD-2025-114382 | B84: 45791 | C84: 45801 | D84: Europe | E84: France | F84: Paris | G84: Small Business | H84: Marketplace | I84: K. Singh | J84: Components | K84: CMP-2865 | L84: 170.39 | M84: 388.04 | N84: 0.084 | O84: 15
A85: ORD-2025-488349 | B85: 45770 | C85: 45769 | D85: Americas | E85: USA | F85: San Francisco | G85: Non-Profit | H85: Distributor | I85: D. Smith | J85: Monitors | K85: MON-3371 | L85: 23.24 | M85: 44.57 | N85: 0.215 | O85: 15
A86: ORD-2025-330203 | B86: 45741 | C86: 45764 | D86: Europe | E86: United Kingdom | F86: London | G86: Consumer | H86: Retail | I86: H. Kim | J86: Networking | K86: NET-7166 | L86: 1421.19 | M86: 1808.26 | N86: 0.104 | O86: 13
A87: ORD-2023-841426 | B87: 45282 | C87: 45283 | D87: Africa | E87: South Africa | F87: Cape Town | G87: Non-Profit | H87: Marketplace | I87: D. Smith | J87: Components | K87: CMP-4531 | L87: 1186.18 | M87: 1285.09 | N87: 0.07 | O87: 11
A88: ORD-2024-594592 | B88: 45388 | C88: 45407 | D88: Asia | E88: China | F88: Shanghai | G88: Corporate | H88: Retail | I88: K. Singh | J88: Components | K88: CMP-8196 | L88: 1366.48 | M88: 1678.14 | N88: 0.154 | O88: 10
A89: ORD-2025-863978 | B89: 45876 | C89: 45888 | D89: Africa | E89: Kenya | F89: Nakuru | G89: Corporate | I89: M. Rossi | J89: Components | K89: CMP-2854 | L89: 601.51 | M89: 679.35 | N89: 0.188 | O89: 3
...

Sheet Staging_Table_1
A1: OrderID | B1: OrderDate | C1: Quarter | D1: Correct_Required_Date | E1: LeadtimeDays | F1: Region | G1: Country | H1: City | I1: CustomerSegment | J1: Channel | K1: Salesperson | L1: ProductCategory | M1: SKU | N1: UnitCost | O1: UnitPrice | P1: Priceband | Q1: DiscountPct | S1: Quantity | T1: Gross Revenue | U1: Cost of Goods | V1: Profit | W1: Margin Pct | X1: Service Level | Y1: Price Compliance | Z1: New Discount | AA1: New Unit Price | AB1: New Unit Cost | AC1: New Quantity | AD1: New Gross Revenue | AE1: New Profit
A2: ORD-2024-275203 | B2: 45362 | C2: ="Q"&ROUNDUP(MONTH(B2)/3,0)&"-"&YEAR(B2) -> Q1-2024 | D2: 45388 | E2: =D2-B2 -> 26 | F2: Africa | G2: Kenya | H2: Kisumu | I2: Corporate | J2: Retail | K2: C. Otieno | L2: Components | M2: CMP-8270 | N2: 279.24 | O2: 608.9 | P2: =IF(O2<=_xlfn.PERCENTILE.INC(IF(L2:L632=L2, O2:O632), 0.33), "Low", IF(O2<=_xlfn.PERCENTILE.INC(IF(L2:L632=L2, O2:O632), 0.66), "Medium", IF(O2 > _xlfn.PERCENTILE.INC(IF(L2:L632=L2, O2:O632), 0.66), "High"))) -> Low | Q2: 0.112 | R2: =IF(Q2<=0.1,"Low",IF(Q2>0.2,"High","Medium")) -> Medium | S2: 9 | T2: 4866.3288 | U2: 2513.16 | V2: 2353.1688 | W2: 0.48356141 | X2: =IF(E2<=7,"On-time","Delayed") -> Delayed | Y2: =IF(Q2<=0.2, "Compliant Discount", "Non-compliant Discount") -> Compliant Discount | Z2: =MIN(Q2,'Scenario Modelling'!$B$2) -> 0.112 | AA2: =O2*(1-Z2) -> 540.7032 | AB2: =N2*(1+'Scenario Modelling'!$B$3) -> 307.164 | AC2: =ROUNDUP(S2*(1+'Scenario Modelling'!$B$4),0) -> 10 | AD2: =AA2*AC2 -> 5407.032 | AE2: =(AA2-AB2)*AC2 -> 2335.392
A3: ORD-2024-358795 | B3: 45588 | C3: ="Q"&ROUNDUP(MONTH(B3)/3,0)&"-"&YEAR(B3) -> Q4-2024 | D3: 45595 | E3: =D3-B3 -> 7 | F3: Africa | G3: Nigeria | H3: Port Harcourt | I3: Education | J3: Online | K3: J. Njeri | L3: Printers | M3: PRN-9322 | N3: 1084.39 | O3: 759.33 | P3: =IF(O3<=_xlfn.PERCENTILE.INC(IF(L3:L633=L3, O3:O633), 0.33), "Low", IF(O3<=_xlfn.PERCENTILE.INC(IF(L3:L633=L3, O3:O633), 0.66), "Medium", IF(O3 > _xlfn.PERCENTILE.INC(IF(L3:L633=L3, O3:O633), 0.66), "High"))) -> Low | Q3: 0.237 | R3: =IF(Q3<=0.1,"Low",IF(Q3>0.2,"High","Medium")) -> High | S3: 31 | T3: 17960.432 | U3: 33616.09 | V3: -15655.658 | W3: -0.87167486 | X3: =IF(E3<=7,"On-time","Delayed") -> On-time | Y3: =IF(Q3<=0.2, "Compliant Discount", "Non-compliant Discount") -> Non-compliant Discount | Z3: =MIN(Q3,'Scenario Modelling'!$B$2) -> 0.2 | AA3: =O3*(1-Z3) -> 607.464 | AB3: =N3*(1+'Scenario Modelling'!$B$3) -> 1192.829 | AC3: =ROUNDUP(S3*(1+'Scenario Modelling'!$B$4),0) -> 33 | AD3: =AA3*AC3 -> 20046.312 | AE3: =(AA3-AB3)*AC3 -> -19317.045
A4: ORD-2023-373538 | B4: 44985 | C4: ="Q"&ROUNDUP(MONTH(B4)/3,0)&"-"&YEAR(B4) -> Q1-2023 | D4: 45010 | E4: =D4-B4 -> 25 | F4: Africa | G4: Kenya | H4: Nairobi | I4: Corporate | J4: Retail | K4: I. Johnson | L4: Networking | M4: NET-9666 | N4: 1460.76 | O4: 30.66 | P4: =IF(O4<=_xlfn.PERCENTILE.INC(IF(L4:L634=L4, O4:O634), 0.33), "Low", IF(O4<=_xlfn.PERCENTILE.INC(IF(L4:L634=L4, O4:O634), 0.66), "Medium", IF(O4 > _xlfn.PERCENTILE.INC(IF(L4:L634=L4, O4:O634), 0.66), "High"))) -> Low | Q4: 0.131 | R4: =IF(Q4<=0.1,"Low",IF(Q4>0.2,"High","Medium")) -> Medium | S4: 12 | T4: 319.72248 | U4: 17529.12 | V4: -17209.398 | W4: -53.826048 | X4: =IF(E4<=7,"On-time","Delayed") -> Delayed | Y4: =IF(Q4<=0.2, "Compliant Discount", "Non-compliant Discount") -> Compliant Discount | Z4: =MIN(Q4,'Scenario Modelling'!$B$2) -> 0.131 | AA4: =O4*(1-Z4) -> 26.64354 | AB4: =N4*(1+'Scenario Modelling'!$B$3) -> 1606.836 | AC4: =ROUNDUP(S4*(1+'Scenario Modelling'!$B$4),0) -> 13 | AD4: =AA4*AC4 -> 346.36602 | AE4: =(AA4-AB4)*AC4 -> -20542.502
A5: ORD-2025-168148 | B5: 45745 | C5: ="Q"&ROUNDUP(MONTH(B5)/3,0)&"-"&YEAR(B5) -> Q1-2025 | D5: 45749 | E5: =D5-B5 -> 4 | F5: Africa | G5: Nigeria | H5: Lagos | I5: Non-Profit | J5: Marketplace | K5: G. Dubois | L5: Phones | M5: PHN-4556 | N5: 259.93 | O5: 255.94 | P5: =IF(O5<=_xlfn.PERCENTILE.INC(IF(L5:L635=L5, O5:O635), 0.33), "Low", IF(O5<=_xlfn.PERCENTILE.INC(IF(L5:L635=L5, O5:O635), 0.66), "Medium", IF(O5 > _xlfn.PERCENTILE.INC(IF(L5:L635=L5, O5:O635), 0.66), "High"))) -> Low | Q5: 0.072 | R5: =IF(Q5<=0.1,"Low",IF(Q5>0.2,"High","Medium")) -> Low | S5: 22 | T5: 5225.271 | U5: 5718.46 | V5: -493.18896 | W5: -0.094385335 | X5: =IF(E5<=7,"On-time","Delayed") -> On-time | Y5: =IF(Q5<=0.2, "Compliant Discount", "Non-compliant Discount") -> Compliant Discount | Z5: =MIN(Q5,'Scenario Modelling'!$B$2) -> 0.072 | AA5: =O5*(1-Z5) -> 237.51232 | AB5: =N5*(1+'Scenario Modelling'!$B$3) -> 285.923 | AC5: =ROUNDUP(S5*(1+'Scenario Modelling'!$B$4),0) -> 24 | AD5: =AA5*AC5 -> 5700.2957 | AE5: =(AA5-AB5)*AC5 -> -1161.8563
A6: ORD-2023-824839 | B6: 45266 | C6: ="Q"&ROUNDUP(MONTH(B6)/3,0)&"-"&YEAR(B6) -> Q4-2023 | D6: 45291 | E6: =D6-B6 -> 25 | F6: Asia | G6: Japan | H6: Osaka | I6: Consumer | J6: Retail | K6: L. Okafor | L6: Printers | M6: PRN-8041 | N6: 663.03 | O6: 813.51 | P6: =IF(O6<=_xlfn.PERCENTILE.INC(IF(L6:L636=L6, O6:O636), 0.33), "Low", IF(O6<=_xlfn.PERCENTILE.INC(IF(L6:L636=L6, O6:O636), 0.66), "Medium", IF(O6 > _xlfn.PERCENTILE.INC(IF(L6:L636=L6, O6:O636), 0.66), "High"))) -> Low | Q6: 0.102 | R6: =IF(Q6<=0.1,"Low",IF(Q6>0.2,"High","Medium")) -> Medium | S6: 15 | T6: 10957.98 | U6: 9945.45 | V6: 1012.5297 | W6: 0.092401129 | X6: =IF(E6<=7,"On-time","Delayed") -> Delayed | Y6: =IF(Q6<=0.2, "Compliant Discount", "Non-compliant Discount") -> Compliant Discount | Z6: =MIN(Q6,'Scenario Modelling'!$B$2) -> 0.102 | AA6: =O6*(1-Z6) -> 730.53198 | AB6: =N6*(1+'Scenario Modelling'!$B$3) -> 729.333 | AC6: =ROUNDUP(S6*(1+'Scenario Modelling'!$B$4),0) -> 16 | AD6: =AA6*AC6 -> 11688.512 | AE6: =(AA6-AB6)*AC6 -> 19.18368
A7: ORD-2023-723587 | B7: 44928 | C7: ="Q"&ROUNDUP(MONTH(B7)/3,0)&"-"&YEAR(B7) -> Q1-2023 | D7: 44931 | E7: =D7-B7 -> 3 | F7: Americas | G7: Canada | H7: Toronto | I7: Corporate | J7: Distributor | K7: B. Chen | L7: Laptops | M7: LAP-8555 | N7: 315.87 | O7: 591.68 | P7: =IF(O7<=_xlfn.PERCENTILE.INC(IF(L7:L637=L7, O7:O637), 0.33), "Low", IF(O7<=_xlfn.PERCENTILE.INC(IF(L7:L637=L7, O7:O637), 0.66), "Medium", IF(O7 > _xlfn.PERCENTILE.INC(IF(L7:L637=L7, O7:O637), 0.66), "High"))) -> Low | Q7: 0 | R7: =IF(Q7<=0.1,"Low",IF(Q7>0.2,"High","Medium")) -> Low | S7: 7 | T7: 4141.76 | U7: 2211.09 | V7: 1930.67 | W7: 0.46614724 | X7: =IF(E7<=7,"On-time","Delayed") -> On-time | Y7: =IF(Q7<=0.2, "Compliant Discount", "Non-compliant Discount") -> Compliant Discount | Z7: =MIN(Q7,'Scenario Modelling'!$B$2) -> 0 | AA7: =O7*(1-Z7) -> 591.68 | AB7: =N7*(1+'Scenario Modelling'!$B$3) -> 347.457 | AC7: =ROUNDUP(S7*(1+'Scenario Modelling'!$B$4),0) -> 8 | AD7: =AA7*AC7 -> 4733.44 | AE7: =(AA7-AB7)*AC7 -> 1953.784
A8: ORD-2024-336584 | B8: 45653 | C8: ="Q"&ROUNDUP(MONTH(B8)/3,0)&"-"&YEAR(B8) -> Q4-2024 | D8: 45671 | E8: =D8-B8 -> 18 | F8: Asia | G8: India | H8: Bengaluru | I8: Small Business | J8: Marketplace | K8: E. Garcia | L8: Monitors | M8: MON-8629 | N8: 586.07 | O8: 845.97 | P8: =IF(O8<=_xlfn.PERCENTILE.INC(IF(L8:L638=L8, O8:O638), 0.33), "Low", IF(O8<=_xlfn.PERCENTILE.INC(IF(L8:L638=L8, O8:O638), 0.66), "Medium", IF(O8 > _xlfn.PERCENTILE.INC(IF(L8:L638=L8, O8:O638), 0.66), "High"))) -> Medium | Q8: 0.147 | R8: =IF(Q8<=0.1,"Low",IF(Q8>0.2,"High","Medium")) -> Medium | S8: 4 | T8: 2886.4496 | U8: 2344.28 | V8: 542.16964 | W8: 0.1878327 | X8: =IF(E8<=7,"On-time","Delayed") -> Delayed | Y8: =IF(Q8<=0.2, "Compliant Discount", "Non-compliant Discount") -> Compliant Discount | Z8: =MIN(Q8,'Scenario Modelling'!$B$2) -> 0.147 | AA8: =O8*(1-Z8) -> 721.61241 | AB8: =N8*(1+'Scenario Modelling'!$B$3) -> 644.677 | AC8: =ROUNDUP(S8*(1+'Scenario Modelling'!$B$4),0) -> 5 | AD8: =AA8*AC8 -> 3608.062 | AE8: =(AA8-AB8)*AC8 -> 384.67705
A9: ORD-2023-112666 | B9: 44941 | C9: ="Q"&ROUNDUP(MONTH(B9)/3,0)&"-"&YEAR(B9) -> Q1-2023 | D9: 44948 | E9: =D9-B9 -> 7 | F9: Africa | G9: Nigeria | H9: Abuja | I9: Education | J9: Online | K9: O. Wang | L9: Printers | M9: PRN-6276 | N9: 28.38 | O9: 47.22 | P9: =IF(O9<=_xlfn.PERCENTILE.INC(IF(L9:L639=L9, O9:O639), 0.33), "Low", IF(O9<=_xlfn.PERCENTILE.INC(IF(L9:L639=L9, O9:O639), 0.66), "Medium", IF(O9 > _xlfn.PERCENTILE.INC(IF(L9:L639=L9, O9:O639), 0.66), "High"))) -> Low | Q9: 0.194 | R9: =IF(Q9<=0.1,"Low",IF(Q9>0.2,"High","Medium")) -> Medium | S9: 18 | T9: 685.06776 | U9: 510.84 | V9: 174.22776 | W9: 0.25432194 | X9: =IF(E9<=7,"On-time","Delayed") -> On-time | Y9: =IF(Q9<=0.2, "Compliant Discount", "Non-compliant Discount") -> Compliant Discount | Z9: =MIN(Q9,'Scenario Modelling'!$B$2) -> 0.194 | AA9: =O9*(1-Z9) -> 38.05932 | AB9: =N9*(1+'Scenario Modelling'!$B$3) -> 31.218 | AC9: =ROUNDUP(S9*(1+'Scenario Modelling'!$B$4),0) -> 19 | AD9: =AA9*AC9 -> 723.12708 | AE9: =(AA9-AB9)*AC9 -> 129.98508
A10: ORD-2024-589570 | B10: 45416 | C10: ="Q"&ROUNDUP(MONTH(B10)/3,0)&"-"&YEAR(B10) -> Q2-2024 | D10: 45441 | E10: =D10-B10 -> 25 | F10: Africa | G10: Nigeria | H10: Abuja | I10: Non-Profit | J10: Marketplace | K10: O. Wang | L10: Monitors | M10: MON-6892 | N10: 1295.34 | O10: 2530.81 | P10: =IF(O10<=_xlfn.PERCENTILE.INC(IF(L10:L640=L10, O10:O640), 0.33), "Low", IF(O10<=_xlfn.PERCENTILE.INC(IF(L10:L640=L10, O10:O640), 0.66), "Medium", IF(O10 > _xlfn.PERCENTILE.INC(IF(L10:L640=L10, O10:O640), 0.66), "High"))) -> High | Q10: 0.031 | R10: =IF(Q10<=0.1,"Low",IF(Q10>0.2,"High","Medium")) -> Low | S10: 6 | T10: 14714.129 | U10: 7772.04 | V10: 6942.0893 | W10: 0.47179749 | X10: =IF(E10<=7,"On-time","Delayed") -> Delayed | Y10: =IF(Q10<=0.2, "Compliant Discount", "Non-compliant Discount") -> Compliant Discount | Z10: =MIN(Q10,'Scenario Modelling'!$B$2) -> 0.031 | AA10: =O10*(1-Z10) -> 2452.3549 | AB10: =N10*(1+'Scenario Modelling'!$B$3) -> 1424.874 | AC10: =ROUNDUP(S10*(1+'Scenario Modelling'!$B$4),0) -> 7 | AD10: =AA10*AC10 -> 17166.484 | AE10: =(AA10-AB10)*AC10 -> 7192.3662
A11: ORD-2025-997421 | B11: 45798 | C11: ="Q"&ROUNDUP(MONTH(B11)/3,0)&"-"&YEAR(B11) -> Q2-2025 | D11: 45817 | E11: =D11-B11 -> 19 | F11: Americas | G11: Brazil | H11: São Paulo | I11: Non-Profit | J11: Online | K11: A. Patel | L11: Components | M11: CMP-3731 | N11: 1331.38 | O11: 2309.56 | P11: =IF(O11<=_xlfn.PERCENTILE.INC(IF(L11:L641=L11, O11:O641), 0.33), "Low", IF(O11<=_xlfn.PERCENTILE.INC(IF(L11:L641=L11, O11:O641), 0.66), "Medium", IF(O11 > _xlfn.PERCENTILE.INC(IF(L11:L641=L11, O11:O641), 0.66), "High"))) -> High | Q11: 0.149 | R11: =IF(Q11<=0.1,"Low",IF(Q11>0.2,"High","Medium")) -> Medium | S11: 31 | T11: 60928.502 | U11: 41272.78 | V11: 19655.722 | W11: 0.32260308 | X11: =IF(E11<=7,"On-time","Delayed") -> Delayed | Y11: =IF(Q11<=0.2, "Compliant Discount", "Non-compliant Discount") -> Compliant Discount | Z11: =MIN(Q11,'Scenario Modelling'!$B$2) -> 0.149 | AA11: =O11*(1-Z11) -> 1965.4356 | AB11: =N11*(1+'Scenario Modelling'!$B$3) -> 1464.518 | AC11: =ROUNDUP(S11*(1+'Scenario Modelling'!$B$4),0) -> 33 | AD11: =AA11*AC11 -> 64859.373 | AE11: =(AA11-AB11)*AC11 -> 16530.279
A12: ORD-2024-210687 | B12: 45319 | C12: ="Q"&ROUNDUP(MONTH(B12)/3,0)&"-"&YEAR(B12) -> Q1-2024 | D12: 45331 | E12: =D12-B12 -> 12 | F12: Europe | G12: Germany | H12: Berlin | I12: Corporate | J12: Online | K12: G. Dubois | L12: Accessories | M12: ACC-7938 | N12: 644.17 | O12: 700.12 | P12: =IF(O12<=_xlfn.PERCENTILE.INC(IF(L12:L642=L12, O12:O642), 0.33), "Low", IF(O12<=_xlfn.PERCENTILE.INC(IF(L12:L642=L12, O12:O642), 0.66), "Medium", IF(O12 > _xlfn.PERCENTILE.INC(IF(L12:L642=L12, O12:O642), 0.66), "High"))) -> Low | Q12: 0.006 | R12: =IF(Q12<=0.1,"Low",IF(Q12>0.2,"High","Medium")) -> Low | S12: 23 | T12: 16006.143 | U12: 14815.91 | V12: 1190.2334 | W12: 0.074361038 | X12: =IF(E12<=7,"On-time","Delayed") -> Delayed | Y12: =IF(Q12<=0.2, "Compliant Discount", "Non-compliant Discount") -> Compliant Discount | Z12: =MIN(Q12,'Scenario Modelling'!$B$2) -> 0.006 | AA12: =O12*(1-Z12) -> 695.91928 | AB12: =N12*(1+'Scenario Modelling'!$B$3) -> 708.587 | AC12: =ROUNDUP(S12*(1+'Scenario Modelling'!$B$4),0) -> 25 | AD12: =AA12*AC12 -> 17397.982 | AE12: =(AA12-AB12)*AC12 -> -316.693
A13: ORD-2025-515515 | B13: 45660 | C13: ="Q"&ROUNDUP(MONTH(B13)/3,0)&"-"&YEAR(B13) -> Q1-2025 | D13: 45680 | E13: =D13-B13 -> 20 | F13: Asia | G13: Japan | H13: Osaka | I13: Corporate | J13: Distributor | K13: F. Müller | L13: Phones | M13: PHN-7019 | N13: 908.6 | O13: 691.37 | P13: =IF(O13<=_xlfn.PERCENTILE.INC(IF(L13:L643=L13, O13:O643), 0.33), "Low", IF(O13<=_xlfn.PERCENTILE.INC(IF(L13:L643=L13, O13:O643), 0.66), "Medium", IF(O13 > _xlfn.PERCENTILE.INC(IF(L13:L643=L13, O13:O643), 0.66), "High"))) -> Low | Q13: 0.25 | R13: =IF(Q13<=0.1,"Low",IF(Q13>0.2,"High","Medium")) -> High | S13: 20 | T13: 10370.55 | U13: 18172 | V13: -7801.45 | W13: -0.75226965 | X13: =IF(E13<=7,"On-time","Delayed") -> Delayed | Y13: =IF(Q13<=0.2, "Compliant Discount", "Non-compliant Discount") -> Non-compliant Discount | Z13: =MIN(Q13,'Scenario Modelling'!$B$2) -> 0.2 | AA13: =O13*(1-Z13) -> 553.096 | AB13: =N13*(1+'Scenario Modelling'!$B$3) -> 999.46 | AC13: =ROUNDUP(S13*(1+'Scenario Modelling'!$B$4),0) -> 21 | AD13: =AA13*AC13 -> 11615.016 | AE13: =(AA13-AB13)*AC13 -> -9373.644
... A632: ORD-2025-728935 | B632: 45716 | C632: ="Q"&ROUNDUP(MONTH(B632)/3,0)&"-"&YEAR(B632) -> Q1-2025 | D632: 45726 | E632: =D632-B632 -> 10 | F632: Asia | G632: Japan | H632: Osaka | I632: Education | J632: Distributor | K632: N. Brown | L632: Laptops | M632: LAP-3017 | N632: 51.86 | O632: 45.98 | P632: =IF(O632<=_xlfn.PERCENTILE.INC(IF(L632:L1262=L632, O632:O1262), 0.33), "Low", IF(O632<=_xlfn.PERCENTILE.INC(IF(L632:L1262=L632, O632:O1262), 0.66), "Medium", IF(O632 > _xlfn.PERCENTILE.INC(IF(L632:L1262=L632, O632:O1262), 0.66), "High"))) -> Low | Q632: 0.173 | R632: =IF(Q632<=0.1,"Low",IF(Q632>0.2,"High","Medium")) -> Medium | S632: 7 | T632: 266.17822 | U632: 363.02 | V632: -96.84178 | W632: -0.36382308 | X632: =IF(E632<=7,"On-time","Delayed") -> Delayed | Y632: =IF(Q632<=0.2, "Compliant Discount", "Non-compliant Discount") -> Compliant Discount | Z632: =MIN(Q632,'Scenario Modelling'!$B$2) -> 0.173 | AA632: =O632*(1-Z632) -> 38.02546 | AB632: =N632*(1+'Scenario Modelling'!$B$3) -> 57.046 | AC632: =ROUNDUP(S632*(1+'Scenario Modelling'!$B$4),0) -> 8 | AD632: =AA632*AC632 -> 304.20368 | AE632: =(AA632-AB632)*AC632 -> -152.16432

Sheet Cohort Analysis
A1: Cohort
A2: Row Labels | B2: Sum of Gross Revenue
A3: Brazil | B3: 1037870.6
A4: 2023
A5: Qtr1 | B5: 51218.845
A6: Qtr2 | B6: 86434.575 | D6: Jan | E6: 1801.4076
A7: Qtr3 | B7: 137832.37
A8: Qtr4 | B8: 101846.59
A9: 2024 | B9: 306190.49
A10: 2025 | B10: 354347.76
A11: Canada | B11: 882622.98
A12: 2023
A13: Qtr1 | B13: 47745.468
A14: Qtr2 | B14: 61844.965 | D14: Jan | E14: 4141.76
A15: Qtr3 | B15: 97693.45
A16: Qtr4 | B16: 42223.383
A17: 2024 | B17: 356412.15
A18: 2025 | B18: 276703.56
A19: China | B19: 899054.11
A20: 2023
A21: Qtr1 | B21: 35713.443
A22: Qtr2 | B22: 78246.004 | D22: Jan | E22: 11406.96
A23: Qtr3 | B23: 78204.903
A24: Qtr4 | B24: 90298.632
A25: 2024 | B25: 431317.1
A26: 2025 | B26: 185274.03
A27: France | B27: 758280.92
A28: 2023
A29: Qtr1 | B29: 49394.01
A30: Qtr2 | B30: 51199.482
A31: Qtr3 | B31: 112195.5 | D31: Jan | E31: 9847.2359
A32: Qtr4 | B32: 56555.235
A33: 2024 | B33: 332686.45
A34: 2025 | B34: 156250.24
A35: Germany | B35: 929424.89
A36: 2023
A37: Qtr1 | B37: 163155.56
A38: Qtr2 | B38: 127787.34
A39: Qtr3 | B39: 14329.267 | D39: Jan | E39: 13921.506
A40: Qtr4 | B40: 64606.506
...

Sheet ABC Analysis
A1: ABC analysis by SKU within each ProductCategory using GrossRevenue
A2: • Classify SKUs into A (top 80%), B (next 15%), C (last 5%) of revenue per category.
A4: Row Labels | B4: Sum of Gross Revenue
A5: Networking | B5: 1774683.1
A6: Laptops | B6: 1711094.4 | D6: 80% - Green
A7: Printers | B7: 1616910.2 | D7: 15% - Yellow
A8: Monitors | B8: 1551590.9 | D8: 5% - Red
A9: Components | B9: 1550200.5
A10: Phones | B10: 1399242.2
A11: Accessories | B11: 1315287.3
A12: Grand Total | B12: 10919009

Sheet Salesperson_Productivity
A2: Salesperson productivity
A3: • Compute Revenue/Order, Orders/Month, and GrossProfit/Order by Salesperson; highlight the top and bottom 3.
A5: Row Labels | B5: Sum of Gross Revenue | C5: Count of OrderID | D5: Sum of Gross Profit
A6: A. Patel | B6: 877449.32 | C6: 46 | D6: 282234.27
A7: B. Chen | B7: 866976.37 | C7: 47 | D7: 320763.18 | F7: Green - Top 3
A8: C. Otieno | B8: 689776.36 | C8: 37 | D8: 230359.52 | F8: Red - Bottom 3
A9: D. Smith | B9: 576820.19 | C9: 38 | D9: 151076.93
A10: E. Garcia | B10: 543846.44 | C10: 34 | D10: 204981.34
A11: F. Müller | B11: 812637.17 | C11: 51 | D11: 251733.01
A12: G. Dubois | B12: 510653.71 | C12: 30 | D12: 172441.87
A13: H. Kim | B13: 698700.3 | C13: 45 | D13: 138152.81
A14: I. Johnson | B14: 541165.67 | C14: 38 | D14: 140021.69
A15: J. Njeri | B15: 802384.66 | C15: 50 | D15: 273113.11
A16: K. Singh | B16: 883348.13 | C16: 44 | D16: 278762.27
A17: L. Okafor | B17: 853476.7 | C17: 46 | D17: 270154.73
A18: M. Rossi | B18: 976696.7 | C18: 48 | D18: 313054.77
A19: N. Brown | B19: 388325.14 | C19: 32 | D19: 110646.46
A20: O. Wang | B20: 647724.9 | C20: 37 | D20: 185219.44
... A22: Grand Total | B22: 10919009 | C22: 631 | D22: 3422813.4

Sheet Channel Mix
A1: Channel mix & cannibalization
A2: • Compare revenue shares by Channel across Regions; identify where online cannibalizes retail (justify with data).
A3: In the Americas, online sales cannibalize retail sales, with each contributing 6.38% & 2.80%, respectively.
A5: Sum of Gross Revenue | B5: Column Labels
A6: Row Labels | B6: Direct | C6: Distributor | D6: Marketplace | E6: Online | F6: Retail | G6: Grand Total
A7: Africa | B7: 0.042730019 | C7: 0.05866193 | D7: 0.048760131 | E7: 0.040064904 | F7: 0.047951612 | G7: 0.2381686
A8: Americas | B8: 0.069505924 | C8: 0.052586813 | D8: 0.033868486 | E8: 0.063780422 | F8: 0.02799636 | G8: 0.247738
A9: Asia | B9: 0.059417331 | C9: 0.047091641 | D9: 0.050483097 | E9: 0.038239655 | F9: 0.061601653 | G9: 0.25683338
A10: Europe | B10: 0.077892879 | C10: 0.029464623 | D10: 0.052661979 | E10: 0.054116108 | F10: 0.043124433 | G10: 0.25726002
A11: Grand Total | B11: 0.24954615 | C11: 0.18780501 | D11: 0.18577369 | E11: 0.19620109 | F11: 0.18067406 | G11: 1

Sheet Service Level
A1: Service level proxy
A2: • Using LeadTimeDays, determine % of orders meeting a 7-day target by Country and Category.
A3: 27.26% of the orders met the 7-day target.
A5: Count of Service Level | B5: Column Labels
A6: Row Labels | B6: Delayed | C6: On-time | D6: Grand Total
A7: Brazil | B7: 0.069730586 | C7: 0.028526149 | D7: 0.098256735
A8: Accessories | B8: 0.0095087163 | C8: 0.0063391442 | D8: 0.015847861 | F8: Created a new column "Service Level" to categorize leadtime into on-time and delayed using the IF function
A9: Components | B9: 0.0095087163 | C9: 0.0015847861 | D9: 0.011093502
A10: Laptops | B10: 0.0063391442 | C10: 0.0015847861 | D10: 0.0079239303
A11: Monitors | B11: 0.014263074 | C11: 0.0047543582 | D11: 0.019017433
A12: Networking | B12: 0.015847861 | C12: 0.0031695721 | D12: 0.019017433
A13: Phones | B13: 0.0063391442 | C13: 0.0079239303 | D13: 0.014263074
A14: Printers | B14: 0.0079239303 | C14: 0.0031695721 | D14: 0.011093502
A15: Canada | B15: 0.055467512 | C15: 0.014263074 | D15: 0.069730586
A16: Accessories | B16: 0.0063391442 | C16: 0.0031695721 | D16: 0.0095087163
A17: Components | B17: 0.0047543582 | C17: 0.0047543582 | D17: 0.0095087163
A18: Laptops | B18: 0.0063391442 | C18: 0.0031695721 | D18: 0.0095087163
A19: Monitors | B19: 0.011093502 | C19: 0 | D19: 0.011093502
A20: Networking | B20: 0.0047543582 | C20: 0 | D20: 0.0047543582
... A103: Grand Total | B103: 0.7274168 | C103: 0.2725832 | D103: 1

Sheet Price Compliance
A1: Price compliance
A2: • Share of orders with DiscountPct > 20% by Region and Salesperson; list outliers.
A4: Count of Price Compliance | B4: Column Labels
A5: Row Labels | B5: Compliant Discount | C5: Non-compliant Discount | D5: Grand Total
A6: Africa | B6: 0.19492868 | C6: 0.034865293 | D6: 0.22979398
A7: A. Patel | B7: 0.020602219 | C7: 0.0047543582 | D7: 0.025356577
A8: B. Chen | B8: 0.012678288 | C8: 0 | D8: 0.012678288
A9: C. Otieno | B9: 0.0095087163 | C9: 0.0031695721 | D9: 0.012678288
A10: D. Smith | B10: 0.012678288 | C10: 0.0031695721 | D10: 0.015847861
A11: E. Garcia | B11: 0.0063391442 | C11: 0.0015847861 | D11: 0.0079239303
A12: F. Müller | B12: 0.020602219 | C12: 0 | D12: 0.020602219
A13: G. Dubois | B13: 0.0047543582 | C13: 0 | D13: 0.0047543582
A14: H. Kim | B14: 0.0095087163 | C14: 0.0015847861 | D14: 0.011093502
A15: I. Johnson | B15: 0.0095087163 | C15: 0.0031695721 | D15: 0.012678288
A16: J. Njeri | B16: 0.014263074 | C16: 0.0047543582 | D16: 0.019017433
A17: K. Singh | B17: 0.022187005 | C17: 0 | D17: 0.022187005
... A74: Grand Total | B74: 0.85895404 | C74: 0.14104596 | D74: 1

Sheet Scenario Modelling
A1: Paraemeter | B1: Input Cell | C1: Value
A2: Discount Cap | B2: 0.2 | C2: 0.2
A3: Cost Inflation | B3: 0.1 | C3: 0.1
A4: Quantity Uplift | B4: 0.05 | C4: 0.05
A8: I used Data Validation to restrict scenario inputs within realistic business limits, ensuring controlled and consistent what-if analysis across all transactions.
A9: The scenario Revenue is higher than the baseline revenue, but the profit is lower.
B12: Row Labels | C12: Sum of Gross Revenue | D12: Sum of New Gross Revenue | E12: Sum of Profit | F12: Sum of New Profit
B13: Africa | C13: 2609130.9 | D13: 2854995.2 | E13: 849158.9 | F13: 758205
B14: Kenya | C14: 947364.87 | D14: 1042064 | E14: 287100.95 | F14: 254253.94
B15: Nigeria | C15: 881838.68 | D15: 956278.9 | E15: 281963.85 | F15: 243445.78
B16: South Africa | C16: 779927.34 | D16: 856652.24 | E16: 280094.1 | F16: 260505.27
B17: Americas | C17: 2689188.2 | D17: 2928587.9 | E17: 862778.95 | F17: 755809.71
B18: Brazil | C18: 1037870.6 | D18: 1128129.9 | E18: 351270.58 | F18: 311287.05
B19: Canada | C19: 882622.98 | D19: 958602.81 | E19: 289819.46 | F19: 255204.87
B20: USA | C20: 768694.59 | D20: 841855.21 | E20: 221688.91 | F20: 189317.8
B21: Asia | C21: 2819701.6 | D21: 3100131.6 | E21: 841039.91 | F21: 734907.12
B22: China | C22: 899054.11 | D22: 992894.62 | E22: 293188.44 | F22: 267205
B23: India | C23: 1065574.1 | D23: 1170591.2 | E23: 292723.8 | F23: 248710.12
B24: Japan | C24: 855073.36 | D24: 936645.78 | E24: 255127.67 | F24: 218992
... B29: Grand Total | C29: 10919009 | D29: 11926922 | E29: 3422813.4 | F29: 2999938.5

Sheet Visuals
A1: Month | B1: Sum of Gross Revenue
A2: Jan | B2: 488911.36
A3: Feb | B3: 677282.25
A4: Mar | B4: 498738.64
A5: Apr | B5: 570270.52
A6: May | B6: 830367.31
A7: Jun | B7: 827973.08
A8: Jul | B8: 767274.63
A9: Aug | B9: 723335.63
A10: Sep | B10: 571228.89
A11: Oct | B11: 395504.23
A12: Nov | B12: 480783.25
A13: Dec | B13: 543596.1
A14: Grand Total | B14: 7375265.9
A18: Sum of Profit | B18: Channel
A19: Region | B19: Direct | C19: Distributor | D19: Marketplace | E19: Online | F19: Retail | G19: Unknown | H19: Grand Total
A20: Africa | B20: 114753.83 | C20: 69059.799 | D20: 2699.974 | E20: 50056.937 | F20: 50680.042 | G20: -149.6334 | H20: 287100.95
A21: Americas | B21: 213382.23 | C21: 133853.28 | D21: 63182.3 | E21: 183963.86 | F21: 46708.375 | H21: 641090.04
A22: Asia | B22: 229541.95 | C22: 151146.75 | D22: 132709.51 | E22: 149042.39 | F22: 158051.77 | G22: 20547.545 | H22: 841039.91
A23: Europe | B23: 228322.7 | C23: 58419.243 | D23: 35348.873 | E23: 102995.33 | F23: 77703.079 | G23: 1263.5065 | H23: 504052.74
A24: Grand Total | B24: 786000.71 | C24: 412479.06 | D24: 233940.66 | E24: 486058.52 | F24: 333143.27 | G24: 21661.419 | H24: 2273283.6
J27: Asia had the highest profit and direct channel contributed the highest percentage of this profit.
A44: Row Labels | B44: Sum of Gross Revenue
A45: CMP-2040 | B45: 65111.386
A46: LAP-8214 | B46: 65119.33
A47: PHN-9677 | B47: 68665.574
A48: MON-5188 | B48: 72665.817
A49: ACC-6626 | B49: 79082.507
A50: NET-5987 | B50: 82141.34
A51: CMP-3938 | B51: 84136.12
A52: MON-6699 | B52: 85637.74
A53: MON-2266 | B53: 87404.93
A54: CMP-8851 | B54: 139277.83
A55: Grand Total | B55: 829242.57
A64: Count of Price Compliance | B64: Column Labels
A65: Row Labels | B65: Compliant Discount | C65: Non-compliant Discount | D65: Grand Total
A66: Canada | B66: 0.082379863 | C66: 0.018306636 | D66: 0.1006865
A67: Germany | B67: 0.10297483 | C67: 0.013729977 | D67: 0.11670481
A68: China | B68: 0.1006865 | C68: 0.016018307 | D68: 0.11670481
A69: France | B69: 0.11212815 | C69: 0.011441648 | D69: 0.12356979
...

Sheet Visuals 2
B1: Count of Service Level | C1: Column Labels
B2: Row Labels | C2: Delayed | D2: On-time | E2: Grand Total
B3: Africa | C3: 0.089244851 | D3: 0.038901602 | E3: 0.12814645
B4: Americas | C4: 0.18077803 | D4: 0.061784897 | E4: 0.24256293 | M4: Africa had the lowest delayed service delivery and on-time delivery, but also contributed the least to sales in terms of order numbers.
B5: Asia | C5: 0.30663616 | D5: 0.082379863 | E5: 0.38901602
B6: Europe | C6: 0.18306636 | D6: 0.057208238 | E6: 0.2402746
B7: Grand Total | C7: 0.7597254 | D7: 0.2402746 | E7: 1
B15: Year | C15: Sum of Cost of Goods
B16: 2023 | C16: 1756098.5
B17: 2024 | C17: 2106216.5
B18: 2025 | C18: 1239667.2
B19: Grand Total | C19: 5101982.3
B30: Row Labels | C30: Average of Cost of Goods
B31: Americas | C31: 11633.18
B32: USA | C32: 10725.602
B33: Brazil | C33: 11074.194
B34: Canada | C34: 13472.807 | F34: On Average Americas has the cheapest cost of goods, therefore, a good region to consider for production. But if we were to consider the cheapest country, then Japan has the cheapest cost of goods on average.
B35: Asia | C35: 11639.186
B36: Japan | C36: 10168.571
B37: China | C37: 11879.719
B38: India | C38: 12880.839
B39: Africa | C39: 12137.738
B40: South Africa | C40: 11107.405
B41: Kenya | C41: 11790.427
B42: Nigeria | C42: 13633.519
B43: Europe | C43: 12145.612
B44: France | C44: 10839.689
B45: Germany | C45: 11731.566
B46: United Kingdom | C46: 13842.578
B47: Grand Total | C47: 11879.866

Sheet Dashboard

Sheet Explanations
A3: Part A — Data Cleaning & Preparation:
A4: 1) Create a staging table where you: A staging table was created by duplicating the raw data sheet to preserve data integrity. All steps were conducted on the staging table while keeping the original data unchanged.
A5: • Remove exact duplicate rows (define and document your duplicate criteria). - Rows were considered duplicates if Order ID were identical.
A6: • Fix data types (dates as Dates, numeric fields as numbers). - Chart, formulas, and Pivot Tables break if data types are wrong.
A7: • Handle missing values for City, Salesperson, and Channel using reasonable business logic (document your approach). - Some records in the dataset contained missing values in key categorical fields, namely City, Salesperson, and Channel. These fields are essential for geographic, performance, and channel-level analysis, and leaving them blank would negatively affect reporting and dashboard accuracy. To address this, missing values were handled using reasonable business logic rather than deleting records or making assumptions. Blank values were replaced with standardized placeholder label such as “Unknown”. This approach preserves all valid transactions while clearly indicating that the original information was not available. By standardizing missing values, the dataset remains complete, consistent, and suitable for aggregation and comparison, without introducing misleading or incorrect data.
A8: • Flag and correct suspicious UnitPrice values (e.g., negative prices) and discounts (e.g., > 30%). Some records contained suspicious pricing values, including negative unit prices and discounts exceeding 30%. Negative unit prices were treated as data entry errors and corrected by Finding and Replacing them to positive values. Discounts above 30% were considered unusually high based on standard business practices and were capped at 30% to prevent distortion of revenue and margin calculations. These corrections ensured realistic pricing while preserving all valid transaction records.
A9: • Ensure RequiredDate is not earlier than OrderDate; where it is, impute a corrected RequiredDate (explain your rule). Some records contained RequiredDate values that were earlier than the corresponding OrderDate, which is logically invalid. These records were corrected by resetting the RequiredDate to a reasonable lead time of seven days after the OrderDate through the use of IF function and named the column "Correct_Required_Date". This ensured chronological consistency while maintaining realistic delivery expectations.
A10: • Add a derived 'LeadTimeDays' = RequiredDate − OrderDate (in days). A derived column, LeadTimeDays, was created to measure the number of days between the OrderDate and the RequiredDate. This metric provides insight into order fulfillment timelines and enables analysis of delivery performance. Since date inconsistencies were resolved earlier, the calculated lead time is accurate and reliable.
A12: 2) Create calculated columns (do these in Excel, not by formula in the data source):
A13: • GrossRevenue = UnitPrice × Quantity × (1 − DiscountPct).
A14: • CostOfGoods = UnitCost × Quantity.
A15: • GrossProfit = GrossRevenue − CostOfGoods.
... A76: 15) Ensure your dashboard responds to slicers without broken references.
